2018-06-19 14:53:40,641 ERROR: Exception on /auth/reset_password_request [POST] [in /Users/eileenwang/protocols/venv/lib/python3.6/site-packages/flask/app.py:1761]
Traceback (most recent call last):
  File "/Users/eileenwang/protocols/venv/lib/python3.6/site-packages/flask/app.py", line 2292, in wsgi_app
    response = self.full_dispatch_request()
  File "/Users/eileenwang/protocols/venv/lib/python3.6/site-packages/flask/app.py", line 1815, in full_dispatch_request
    rv = self.handle_user_exception(e)
  File "/Users/eileenwang/protocols/venv/lib/python3.6/site-packages/flask/app.py", line 1718, in handle_user_exception
    reraise(exc_type, exc_value, tb)
  File "/Users/eileenwang/protocols/venv/lib/python3.6/site-packages/flask/_compat.py", line 35, in reraise
    raise value
  File "/Users/eileenwang/protocols/venv/lib/python3.6/site-packages/flask/app.py", line 1813, in full_dispatch_request
    rv = self.dispatch_request()
  File "/Users/eileenwang/protocols/venv/lib/python3.6/site-packages/flask/app.py", line 1799, in dispatch_request
    return self.view_functions[rule.endpoint](**req.view_args)
  File "/Users/eileenwang/protocols/app/auth/routes.py", line 60, in reset_password_request
    send_password_reset_email(user)
  File "/Users/eileenwang/protocols/app/auth/email.py", line 6, in send_password_reset_email
    token = user.get_reset_password_token()
  File "/Users/eileenwang/protocols/app/models.py", line 35, in get_reset_password_token
    {'reset_password': self.id, 'exp': time() + expires_in},
NameError: name 'time' is not defined
2018-06-19 14:55:07,107 INFO: Protocols startup [in /Users/eileenwang/protocols/app/__init__.py:69]
2018-06-19 14:55:35,200 ERROR: Exception on /auth/reset_password_request [POST] [in /Users/eileenwang/protocols/venv/lib/python3.6/site-packages/flask/app.py:1761]
Traceback (most recent call last):
  File "/Users/eileenwang/protocols/venv/lib/python3.6/site-packages/flask/app.py", line 2292, in wsgi_app
    response = self.full_dispatch_request()
  File "/Users/eileenwang/protocols/venv/lib/python3.6/site-packages/flask/app.py", line 1815, in full_dispatch_request
    rv = self.handle_user_exception(e)
  File "/Users/eileenwang/protocols/venv/lib/python3.6/site-packages/flask/app.py", line 1718, in handle_user_exception
    reraise(exc_type, exc_value, tb)
  File "/Users/eileenwang/protocols/venv/lib/python3.6/site-packages/flask/_compat.py", line 35, in reraise
    raise value
  File "/Users/eileenwang/protocols/venv/lib/python3.6/site-packages/flask/app.py", line 1813, in full_dispatch_request
    rv = self.dispatch_request()
  File "/Users/eileenwang/protocols/venv/lib/python3.6/site-packages/flask/app.py", line 1799, in dispatch_request
    return self.view_functions[rule.endpoint](**req.view_args)
  File "/Users/eileenwang/protocols/app/auth/routes.py", line 60, in reset_password_request
    send_password_reset_email(user)
  File "/Users/eileenwang/protocols/app/auth/email.py", line 6, in send_password_reset_email
    token = user.get_reset_password_token()
  File "/Users/eileenwang/protocols/app/models.py", line 37, in get_reset_password_token
    current_app.config['SECRET_KEY'],
NameError: name 'current_app' is not defined
2018-06-19 14:56:14,930 INFO: Protocols startup [in /Users/eileenwang/protocols/app/__init__.py:69]
2018-06-19 14:56:27,151 ERROR: Exception on /auth/reset_password_request [POST] [in /Users/eileenwang/protocols/venv/lib/python3.6/site-packages/flask/app.py:1761]
Traceback (most recent call last):
  File "/Users/eileenwang/protocols/venv/lib/python3.6/site-packages/flask/app.py", line 2292, in wsgi_app
    response = self.full_dispatch_request()
  File "/Users/eileenwang/protocols/venv/lib/python3.6/site-packages/flask/app.py", line 1815, in full_dispatch_request
    rv = self.handle_user_exception(e)
  File "/Users/eileenwang/protocols/venv/lib/python3.6/site-packages/flask/app.py", line 1718, in handle_user_exception
    reraise(exc_type, exc_value, tb)
  File "/Users/eileenwang/protocols/venv/lib/python3.6/site-packages/flask/_compat.py", line 35, in reraise
    raise value
  File "/Users/eileenwang/protocols/venv/lib/python3.6/site-packages/flask/app.py", line 1813, in full_dispatch_request
    rv = self.dispatch_request()
  File "/Users/eileenwang/protocols/venv/lib/python3.6/site-packages/flask/app.py", line 1799, in dispatch_request
    return self.view_functions[rule.endpoint](**req.view_args)
  File "/Users/eileenwang/protocols/app/auth/routes.py", line 60, in reset_password_request
    send_password_reset_email(user)
  File "/Users/eileenwang/protocols/app/auth/email.py", line 11, in send_password_reset_email
    user=user, token=token),
  File "/Users/eileenwang/protocols/venv/lib/python3.6/site-packages/flask/templating.py", line 135, in render_template
    context, ctx.app)
  File "/Users/eileenwang/protocols/venv/lib/python3.6/site-packages/flask/templating.py", line 117, in _render
    rv = template.render(context)
  File "/Users/eileenwang/protocols/venv/lib/python3.6/site-packages/jinja2/asyncsupport.py", line 76, in render
    return original_render(self, *args, **kwargs)
  File "/Users/eileenwang/protocols/venv/lib/python3.6/site-packages/jinja2/environment.py", line 1008, in render
    return self.environment.handle_exception(exc_info, True)
  File "/Users/eileenwang/protocols/venv/lib/python3.6/site-packages/jinja2/environment.py", line 780, in handle_exception
    reraise(exc_type, exc_value, tb)
  File "/Users/eileenwang/protocols/venv/lib/python3.6/site-packages/jinja2/_compat.py", line 37, in reraise
    raise value.with_traceback(tb)
  File "/Users/eileenwang/protocols/app/templates/email/reset_password.txt", line 5, in top-level template code
    {{ url_for('reset_password', token=token, _external=True) }}
  File "/Users/eileenwang/protocols/venv/lib/python3.6/site-packages/flask/helpers.py", line 356, in url_for
    return appctx.app.handle_url_build_error(error, endpoint, values)
  File "/Users/eileenwang/protocols/venv/lib/python3.6/site-packages/flask/app.py", line 2061, in handle_url_build_error
    reraise(exc_type, exc_value, tb)
  File "/Users/eileenwang/protocols/venv/lib/python3.6/site-packages/flask/_compat.py", line 35, in reraise
    raise value
  File "/Users/eileenwang/protocols/venv/lib/python3.6/site-packages/flask/helpers.py", line 345, in url_for
    force_external=external)
  File "/Users/eileenwang/protocols/venv/lib/python3.6/site-packages/werkzeug/routing.py", line 1776, in build
    raise BuildError(endpoint, values, method, self)
werkzeug.routing.BuildError: Could not build url for endpoint 'reset_password' with values ['token']. Did you mean 'auth.reset_password' instead?
2018-06-19 14:57:27,341 INFO: Protocols startup [in /Users/eileenwang/protocols/app/__init__.py:69]
2018-06-19 15:02:53,531 INFO: Protocols startup [in /Users/eileenwang/protocols/app/__init__.py:69]
2018-06-20 00:43:52,739 INFO: Protocols startup [in /Users/eileenwang/protocols/app/__init__.py:69]
