2018-07-10 09:07:41,881 ERROR: Exception on /index/ [GET] [in /Users/eileenwang/protocols/venv/lib/python3.6/site-packages/flask/app.py:1761]
Traceback (most recent call last):
  File "/Users/eileenwang/protocols/venv/lib/python3.6/site-packages/flask/app.py", line 2292, in wsgi_app
    response = self.full_dispatch_request()
  File "/Users/eileenwang/protocols/venv/lib/python3.6/site-packages/flask/app.py", line 1815, in full_dispatch_request
    rv = self.handle_user_exception(e)
  File "/Users/eileenwang/protocols/venv/lib/python3.6/site-packages/flask/app.py", line 1718, in handle_user_exception
    reraise(exc_type, exc_value, tb)
  File "/Users/eileenwang/protocols/venv/lib/python3.6/site-packages/flask/_compat.py", line 35, in reraise
    raise value
  File "/Users/eileenwang/protocols/venv/lib/python3.6/site-packages/flask/app.py", line 1813, in full_dispatch_request
    rv = self.dispatch_request()
  File "/Users/eileenwang/protocols/venv/lib/python3.6/site-packages/flask/app.py", line 1799, in dispatch_request
    return self.view_functions[rule.endpoint](**req.view_args)
  File "/Users/eileenwang/protocols/venv/lib/python3.6/site-packages/flask_login/utils.py", line 261, in decorated_view
    return func(*args, **kwargs)
  File "/Users/eileenwang/protocols/app/main/routes.py", line 22, in index
    cur.execute("SELECT JSON_text FROM Protocols ORDER BY version_id DESC LIMIT 1")
sqlite3.OperationalError: no such table: Protocols
2018-07-10 09:08:38,464 INFO: Protocols startup [in /Users/eileenwang/protocols/app/__init__.py:74]
2018-07-10 09:08:40,912 ERROR: Exception on /index/ [GET] [in /Users/eileenwang/protocols/venv/lib/python3.6/site-packages/flask/app.py:1761]
Traceback (most recent call last):
  File "/Users/eileenwang/protocols/venv/lib/python3.6/site-packages/flask/app.py", line 2292, in wsgi_app
    response = self.full_dispatch_request()
  File "/Users/eileenwang/protocols/venv/lib/python3.6/site-packages/flask/app.py", line 1815, in full_dispatch_request
    rv = self.handle_user_exception(e)
  File "/Users/eileenwang/protocols/venv/lib/python3.6/site-packages/flask/app.py", line 1718, in handle_user_exception
    reraise(exc_type, exc_value, tb)
  File "/Users/eileenwang/protocols/venv/lib/python3.6/site-packages/flask/_compat.py", line 35, in reraise
    raise value
  File "/Users/eileenwang/protocols/venv/lib/python3.6/site-packages/flask/app.py", line 1813, in full_dispatch_request
    rv = self.dispatch_request()
  File "/Users/eileenwang/protocols/venv/lib/python3.6/site-packages/flask/app.py", line 1799, in dispatch_request
    return self.view_functions[rule.endpoint](**req.view_args)
  File "/Users/eileenwang/protocols/venv/lib/python3.6/site-packages/flask_login/utils.py", line 261, in decorated_view
    return func(*args, **kwargs)
  File "/Users/eileenwang/protocols/app/main/routes.py", line 22, in index
    cur.execute("SELECT JSON_text FROM Protocols ORDER BY version_id DESC LIMIT 1")
sqlite3.OperationalError: no such table: Protocols
2018-07-10 09:10:44,363 INFO: Protocols startup [in /Users/eileenwang/protocols/app/__init__.py:74]
2018-07-16 01:12:34,904 INFO: Protocols startup [in /Users/eileenwang/protocols/app/__init__.py:79]
