2018-07-03 15:36:02,249 ERROR: Exception on / [GET] [in /Users/eileenwang/protocols/venv/lib/python3.6/site-packages/flask/app.py:1761]
Traceback (most recent call last):
  File "/Users/eileenwang/protocols/venv/lib/python3.6/site-packages/flask/app.py", line 2292, in wsgi_app
    response = self.full_dispatch_request()
  File "/Users/eileenwang/protocols/venv/lib/python3.6/site-packages/flask/app.py", line 1815, in full_dispatch_request
    rv = self.handle_user_exception(e)
  File "/Users/eileenwang/protocols/venv/lib/python3.6/site-packages/flask/app.py", line 1718, in handle_user_exception
    reraise(exc_type, exc_value, tb)
  File "/Users/eileenwang/protocols/venv/lib/python3.6/site-packages/flask/_compat.py", line 35, in reraise
    raise value
  File "/Users/eileenwang/protocols/venv/lib/python3.6/site-packages/flask/app.py", line 1813, in full_dispatch_request
    rv = self.dispatch_request()
  File "/Users/eileenwang/protocols/venv/lib/python3.6/site-packages/flask/app.py", line 1799, in dispatch_request
    return self.view_functions[rule.endpoint](**req.view_args)
  File "/Users/eileenwang/protocols/venv/lib/python3.6/site-packages/flask_login/utils.py", line 261, in decorated_view
    return func(*args, **kwargs)
  File "/Users/eileenwang/protocols/app/main/routes.py", line 27, in index
    for k1, v1 in data['IRM'].items():
TypeError: list indices must be integers or slices, not str
2018-07-03 15:36:27,292 INFO: Protocols startup [in /Users/eileenwang/protocols/app/__init__.py:69]
2018-07-03 15:36:28,797 ERROR: Exception on / [GET] [in /Users/eileenwang/protocols/venv/lib/python3.6/site-packages/flask/app.py:1761]
Traceback (most recent call last):
  File "/Users/eileenwang/protocols/venv/lib/python3.6/site-packages/flask/app.py", line 2292, in wsgi_app
    response = self.full_dispatch_request()
  File "/Users/eileenwang/protocols/venv/lib/python3.6/site-packages/flask/app.py", line 1815, in full_dispatch_request
    rv = self.handle_user_exception(e)
  File "/Users/eileenwang/protocols/venv/lib/python3.6/site-packages/flask/app.py", line 1718, in handle_user_exception
    reraise(exc_type, exc_value, tb)
  File "/Users/eileenwang/protocols/venv/lib/python3.6/site-packages/flask/_compat.py", line 35, in reraise
    raise value
  File "/Users/eileenwang/protocols/venv/lib/python3.6/site-packages/flask/app.py", line 1813, in full_dispatch_request
    rv = self.dispatch_request()
  File "/Users/eileenwang/protocols/venv/lib/python3.6/site-packages/flask/app.py", line 1799, in dispatch_request
    return self.view_functions[rule.endpoint](**req.view_args)
  File "/Users/eileenwang/protocols/venv/lib/python3.6/site-packages/flask_login/utils.py", line 261, in decorated_view
    return func(*args, **kwargs)
  File "/Users/eileenwang/protocols/app/main/routes.py", line 28, in index
    for k1, v1 in data['IRM'].items():
TypeError: list indices must be integers or slices, not str
2018-07-03 15:37:28,092 INFO: Protocols startup [in /Users/eileenwang/protocols/app/__init__.py:69]
2018-07-03 15:37:29,560 ERROR: Exception on / [GET] [in /Users/eileenwang/protocols/venv/lib/python3.6/site-packages/flask/app.py:1761]
Traceback (most recent call last):
  File "/Users/eileenwang/protocols/venv/lib/python3.6/site-packages/flask/app.py", line 2292, in wsgi_app
    response = self.full_dispatch_request()
  File "/Users/eileenwang/protocols/venv/lib/python3.6/site-packages/flask/app.py", line 1815, in full_dispatch_request
    rv = self.handle_user_exception(e)
  File "/Users/eileenwang/protocols/venv/lib/python3.6/site-packages/flask/app.py", line 1718, in handle_user_exception
    reraise(exc_type, exc_value, tb)
  File "/Users/eileenwang/protocols/venv/lib/python3.6/site-packages/flask/_compat.py", line 35, in reraise
    raise value
  File "/Users/eileenwang/protocols/venv/lib/python3.6/site-packages/flask/app.py", line 1813, in full_dispatch_request
    rv = self.dispatch_request()
  File "/Users/eileenwang/protocols/venv/lib/python3.6/site-packages/flask/app.py", line 1799, in dispatch_request
    return self.view_functions[rule.endpoint](**req.view_args)
  File "/Users/eileenwang/protocols/venv/lib/python3.6/site-packages/flask_login/utils.py", line 261, in decorated_view
    return func(*args, **kwargs)
  File "/Users/eileenwang/protocols/app/main/routes.py", line 29, in index
    for k1, v1 in data['IRM'].items():
TypeError: list indices must be integers or slices, not str
2018-07-03 15:40:40,145 INFO: Protocols startup [in /Users/eileenwang/protocols/app/__init__.py:69]
2018-07-03 15:40:43,134 ERROR: Exception on / [GET] [in /Users/eileenwang/protocols/venv/lib/python3.6/site-packages/flask/app.py:1761]
Traceback (most recent call last):
  File "/Users/eileenwang/protocols/venv/lib/python3.6/site-packages/flask/app.py", line 2292, in wsgi_app
    response = self.full_dispatch_request()
  File "/Users/eileenwang/protocols/venv/lib/python3.6/site-packages/flask/app.py", line 1815, in full_dispatch_request
    rv = self.handle_user_exception(e)
  File "/Users/eileenwang/protocols/venv/lib/python3.6/site-packages/flask/app.py", line 1718, in handle_user_exception
    reraise(exc_type, exc_value, tb)
  File "/Users/eileenwang/protocols/venv/lib/python3.6/site-packages/flask/_compat.py", line 35, in reraise
    raise value
  File "/Users/eileenwang/protocols/venv/lib/python3.6/site-packages/flask/app.py", line 1813, in full_dispatch_request
    rv = self.dispatch_request()
  File "/Users/eileenwang/protocols/venv/lib/python3.6/site-packages/flask/app.py", line 1799, in dispatch_request
    return self.view_functions[rule.endpoint](**req.view_args)
  File "/Users/eileenwang/protocols/venv/lib/python3.6/site-packages/flask_login/utils.py", line 261, in decorated_view
    return func(*args, **kwargs)
  File "/Users/eileenwang/protocols/app/main/routes.py", line 21, in index
    cur.execute("SELECT JSON_text FROM Protocoles ORDER BY version_id DESC LIMIT 1")
sqlite3.OperationalError: no such table: Protocoles
2018-07-03 15:41:06,741 INFO: Protocols startup [in /Users/eileenwang/protocols/app/__init__.py:69]
2018-07-03 15:41:08,031 ERROR: Exception on / [GET] [in /Users/eileenwang/protocols/venv/lib/python3.6/site-packages/flask/app.py:1761]
Traceback (most recent call last):
  File "/Users/eileenwang/protocols/venv/lib/python3.6/site-packages/flask/app.py", line 2292, in wsgi_app
    response = self.full_dispatch_request()
  File "/Users/eileenwang/protocols/venv/lib/python3.6/site-packages/flask/app.py", line 1815, in full_dispatch_request
    rv = self.handle_user_exception(e)
  File "/Users/eileenwang/protocols/venv/lib/python3.6/site-packages/flask/app.py", line 1718, in handle_user_exception
    reraise(exc_type, exc_value, tb)
  File "/Users/eileenwang/protocols/venv/lib/python3.6/site-packages/flask/_compat.py", line 35, in reraise
    raise value
  File "/Users/eileenwang/protocols/venv/lib/python3.6/site-packages/flask/app.py", line 1813, in full_dispatch_request
    rv = self.dispatch_request()
  File "/Users/eileenwang/protocols/venv/lib/python3.6/site-packages/flask/app.py", line 1799, in dispatch_request
    return self.view_functions[rule.endpoint](**req.view_args)
  File "/Users/eileenwang/protocols/venv/lib/python3.6/site-packages/flask_login/utils.py", line 261, in decorated_view
    return func(*args, **kwargs)
  File "/Users/eileenwang/protocols/app/main/routes.py", line 24, in index
    dict(data)
ValueError: dictionary update sequence element #0 has length 1; 2 is required
2018-07-03 15:41:29,712 INFO: Protocols startup [in /Users/eileenwang/protocols/app/__init__.py:69]
2018-07-03 15:41:31,491 ERROR: Exception on / [GET] [in /Users/eileenwang/protocols/venv/lib/python3.6/site-packages/flask/app.py:1761]
Traceback (most recent call last):
  File "/Users/eileenwang/protocols/venv/lib/python3.6/site-packages/flask/app.py", line 2292, in wsgi_app
    response = self.full_dispatch_request()
  File "/Users/eileenwang/protocols/venv/lib/python3.6/site-packages/flask/app.py", line 1815, in full_dispatch_request
    rv = self.handle_user_exception(e)
  File "/Users/eileenwang/protocols/venv/lib/python3.6/site-packages/flask/app.py", line 1718, in handle_user_exception
    reraise(exc_type, exc_value, tb)
  File "/Users/eileenwang/protocols/venv/lib/python3.6/site-packages/flask/_compat.py", line 35, in reraise
    raise value
  File "/Users/eileenwang/protocols/venv/lib/python3.6/site-packages/flask/app.py", line 1813, in full_dispatch_request
    rv = self.dispatch_request()
  File "/Users/eileenwang/protocols/venv/lib/python3.6/site-packages/flask/app.py", line 1799, in dispatch_request
    return self.view_functions[rule.endpoint](**req.view_args)
  File "/Users/eileenwang/protocols/venv/lib/python3.6/site-packages/flask_login/utils.py", line 261, in decorated_view
    return func(*args, **kwargs)
  File "/Users/eileenwang/protocols/app/main/routes.py", line 24, in index
    dict(data)
ValueError: dictionary update sequence element #0 has length 1; 2 is required
2018-07-03 15:41:53,109 INFO: Protocols startup [in /Users/eileenwang/protocols/app/__init__.py:69]
